Workbook

Sheet Costs
A2: Costs Incurred Breakdown
A3: Item Cost | B3: 35255.88
A4: Freight | B4: 11749.98
A5: Duty Charges | B5: 1352.57 | C5: 0.05
A6: GST | B6: - | C6: 0.08
A7: Broker Charges | B7: 1814.4
A8: Claude Sub | B8: 2420
A9: Chatgpt Sub | B9: 440
A10: Grok Sub | B10: 660
A11: Business Card | B11: 2200
A12: Bags | B12: 3300 | F12: Total cost | G12: 69267.83 | J12: =(43.12/G14)*G12 -> 294.85275
A13: Box | B13: 3300 | F13: No. Quantity | G13: 420
A14: Packaging Compliments | B14: 1540 | F14: Per Unit CNF | G14: 10129.9
A15: Sample Bottles | B15: 1100 | C15: =SUM(B10:B15) -> 12100
A16: GoDaddy 1 Year Sub | B16: 755
A17: Logo Sub 6 months | B17: 300
A18: Partnership Registration | B18: 2000
A19: Business Name Registration | B19: 200
A20: Business Activity Registration | B20: 150
A21: Stamp Registration and Making | B21: 430
A22: Dhiraagu Domain | B22: 300
A23: Total | B23: =SUM(B3:B22) -> 69267.83 | C23: =B23/420 -> 164.9234
C24: =((B23/420)/2.5) -> 65.969362
A26: TOTAL REALIZED | B26: =B23-C15 -> 57167.83

Sheet Pricing WorkSheet
A1: Product Name (as invoiced) | B1: Category | C1: Qty (NOS) | D1: CNF / Unit (invoiced USD) | E1: CNF / Total Units (invoiced USD) | F1: CNF / Unit (MVR) | G1: CNF / Total Units (MVR) | H1: Lebelage Price w/o Shipping (MVR) | I1: Yesstyle Prices w/o Shipping (MVR) | J1: Base Profit / Unit (MVR) | K1: Weighted max expense (MVR) | L1: Selling price w/o GST (MVR) | M1: GST 8% (MVR) | N1: Total Selling Price / Unit (MVR) | O1: Total Selling Price / Total Units (MVR) | P1: Proposed New Selling Price / Unit (MVR) | Q1: Lebelage Retail Price as per Kim's Catalogue (USD) | R1: Lebelage Retail Price as per Kim's Catalogue (MVR) | S1: Lebelage Price w/o Shipping (MVR)2 | T1: Lebelage Retail Price (USD) | U1: CNF / Unit (invoiced USD)2 | V1: CNF / Unit (MVR)2 | W1: Yesstyle Prices w/o Shipping (MVR)2 | X1: Total Selling Price / Unit (MVR)2 | Y1: Minimum Selling Price w/o GST (MVR) | Z1: Minimum Selling Price w/ GST (MVR) | AA1: Minimum Selling Price w/ GST for Total Units (MVR) | AB1: Alt 1 Median Selling Price w/o GST (MVR) | AC1: Alt 1 Median Selling Price w/ GST (MVR) | AD1: Alt 1 Median Selling Price w/ GST for Total Units (MVR) | AE1: Alt 2 Median Selling Price w/o GST (MVR)2 | AF1: Alt 2 Median Selling Price w/ GST (MVR)2 | AG1: Alt 2 Median Selling Price w/ GST for Total Units (MVR) | AH1: Maximum Selling Price w/o GST (MVR) | AI1: Maximum Selling Price w/ GST (MVR) | AJ1: Maximum Selling Price w/ GST for Total Units (MVR)2 | AK1: Revenue to CNF ratio (%) | AL1: Profit / Unit (MVR) | AM1: Total Profit (MVR)
N2: Current Price | O2: Current Expected Revenue on 100% sales | P2: Final Price | R2: Kim's Lebelage Catalogue | S2: Lebelage Website Price w/o Shipping | V2: CNF | W2: Yesstyle Price w/o Shipping | Y2: (Lebelage selling price)*15.42 | Z2: Per Product | AA2: "Minimum Selling Price" Revenue on 100% sales | AB2: (Lebelage selling price + 9 usd shipping)*15.42 | AC2: Per Product | AD2: "Alt 1 Median Selling Price" Revenue on 100% sales | AE2: (Lebelage selling price)*22 | AF2: Per Product | AG2: "Alt 2 Median Selling Price" Revenue on 100% sales | AH2: (Lebelage selling price + 9usd shipping)*22 | AI2: Per Product | AJ2: "Maximum Selling Price" Revenue on 100% sales
A3: Aloe Bubble Chewy Foam 200ml | B3: Cleansing & Peeling | C3: 4 | D3: 7.06 | E3: 28.24 | F3: =D3*22 -> 155.32 | G3: =SUM(F3*C3) -> 621.28 | H3: 487.52 | I3: 322.74 | J3: =L3-K3 -> 140.65438 | K3: =(F3/$G$92)*Costs!$B$23 -> 229.71599 | L3: =N3/1.08 -> 370.37037 | M3: =L3*0.08 -> 29.62963 | N3: 400 | O3: =Table1[[#This Row],[Total Selling Price / Unit (MVR)]]*Table1[[#This Row],[Qty (NOS)]] -> 1600 | Q3: 21.36 | R3: =Q3*22 -> 469.92 | S3: 487.52 | T3: 22.16 | U3: 7.06 | V3: 155.32 | W3: 322.74 | X3: 400 | Y3: =T3*15.42 -> 341.7072 | Z3: =Y3*1.08 -> 369.04378 | AA3: =C3*Z3 -> 1476.1751 | AB3: =(T3+9)*15.42 -> 480.4872 | AC3: =AB3*1.08 -> 518.92618 | AD3: =C3*AC3 -> 2075.7047 | AE3: =T3*22 -> 487.52 | AF3: =AE3*1.08 -> 526.5216 | AG3: =C3*AF3 -> 2106.0864 | AH3: =(T3+9)*22 -> 685.52 | AI3: =AH3*1.08 -> 740.3616 | AJ3: =C3*AI3 -> 2961.4464 | AK3: =Table1[[#This Row],[Total Selling Price / Unit (MVR)]]/Table1[[#This Row],[CNF / Unit (MVR)]] -> 2.5753284 | AL3: =Table1[[#This Row],[Total Selling Price / Unit (MVR)]]-(Table1[[#This Row],[GST 8% (MVR)]]+Table1[[#This Row],[Weighted max expense (MVR)]]) -> 140.65438 | AM3: =Table1[[#This Row],[Profit / Unit (MVR)]]*Table1[[#This Row],[Qty (NOS)]] -> 562.61753
A4: AVOCADO REVITAL CLEANSING FOAM 180ml | B4: Cleansing & Peeling | C4: 4 | D4: 3.9 | E4: 15.6 | F4: =D4*22 -> 85.8 | G4: =SUM(F4*C4) -> 343.2 | H4: 119.02 | I4: 176.22 | J4: =L4-K4 -> 39.769733 | K4: =(F4/$G$92)*Costs!$B$23 -> 126.89693 | L4: =N4/1.08 -> 166.66667 | M4: =L4*0.08 -> 13.333333 | N4: 180 | O4: =Table1[[#This Row],[Total Selling Price / Unit (MVR)]]*Table1[[#This Row],[Qty (NOS)]] -> 720 | Q4: 5.21 | R4: =Q4*22 -> 114.62 | S4: 119.02 | T4: 5.41 | U4: 3.9 | V4: 85.8 | W4: 176.22 | X4: 180 | Y4: =T4*15.42 -> 83.4222 | Z4: =Y4*1.08 -> 90.095976 | AA4: =C4*Z4 -> 360.3839 | AB4: =(T4+9)*15.42 -> 222.2022 | AC4: =AB4*1.08 -> 239.97838 | AD4: =C4*AC4 -> 959.9135 | AE4: =T4*22 -> 119.02 | AF4: =AE4*1.08 -> 128.5416 | AG4: =C4*AF4 -> 514.1664 | AH4: =(T4+9)*22 -> 317.02 | AI4: =AH4*1.08 -> 342.3816 | AJ4: =C4*AI4 -> 1369.5264 | AK4: =Table1[[#This Row],[Total Selling Price / Unit (MVR)]]/Table1[[#This Row],[CNF / Unit (MVR)]] -> 2.0979021 | AL4: =Table1[[#This Row],[Total Selling Price / Unit (MVR)]]-(Table1[[#This Row],[GST 8% (MVR)]]+Table1[[#This Row],[Weighted max expense (MVR)]]) -> 39.769733 | AM4: =Table1[[#This Row],[Profit / Unit (MVR)]]*Table1[[#This Row],[Qty (NOS)]] -> 159.07893 | AO4: Total Revenue | AP4: =O92 -> 136161
A5: Centella Bubble Chewy Foam 200ml | B5: Cleansing & Peeling | C5: 7 | D5: 7.06 | E5: 49.42 | F5: =D5*22 -> 155.32 | G5: =SUM(F5*C5) -> 1087.24 | H5: 487.52 | I5: 322.74 | J5: =L5-K5 -> 140.65438 | K5: =(F5/$G$92)*Costs!$B$23 -> 229.71599 | L5: =N5/1.08 -> 370.37037 | M5: =L5*0.08 -> 29.62963 | N5: 400 | O5: =Table1[[#This Row],[Total Selling Price / Unit (MVR)]]*Table1[[#This Row],[Qty (NOS)]] -> 2800 | Q5: 21.36 | R5: =Q5*22 -> 469.92 | S5: 487.52 | T5: 22.16 | U5: 7.06 | V5: 155.32 | W5: 322.74 | X5: 400 | Y5: =T5*15.42 -> 341.7072 | Z5: =Y5*1.08 -> 369.04378 | AA5: =C5*Z5 -> 2583.3064 | AB5: =(T5+9)*15.42 -> 480.4872 | AC5: =AB5*1.08 -> 518.92618 | AD5: =C5*AC5 -> 3632.4832 | AE5: =T5*22 -> 487.52 | AF5: =AE5*1.08 -> 526.5216 | AG5: =C5*AF5 -> 3685.6512 | AH5: =(T5+9)*22 -> 685.52 | AI5: =AH5*1.08 -> 740.3616 | AJ5: =C5*AI5 -> 5182.5312 | AK5: =Table1[[#This Row],[Total Selling Price / Unit (MVR)]]/Table1[[#This Row],[CNF / Unit (MVR)]] -> 2.5753284 | AL5: =Table1[[#This Row],[Total Selling Price / Unit (MVR)]]-(Table1[[#This Row],[GST 8% (MVR)]]+Table1[[#This Row],[Weighted max expense (MVR)]]) -> 140.65438 | AM5: =Table1[[#This Row],[Profit / Unit (MVR)]]*Table1[[#This Row],[Qty (NOS)]] -> 984.58068 | AO5: Total Cost | AP5: =Costs!B23 -> 69267.83
A6: Charcoal Clay 2in1 Pack Foam 120ml | B6: Cleansing & Peeling | C6: 7 | D6: 4.24 | E6: 29.68 | F6: =D6*22 -> 93.28 | G6: =SUM(F6*C6) -> 652.96 | H6: 407.66 | I6: 162.36 | J6: =L6-K6 -> 186.11433 | K6: =(F6/$G$92)*Costs!$B$23 -> 137.95974 | L6: =N6/1.08 -> 324.07407 | M6: =L6*0.08 -> 25.925926 | N6: 350 | O6: =Table1[[#This Row],[Total Selling Price / Unit (MVR)]]*Table1[[#This Row],[Qty (NOS)]] -> 2450 | Q6: 17.86 | R6: =Q6*22 -> 392.92 | S6: 407.66 | T6: 18.53 | U6: 4.24 | V6: 93.28 | W6: 162.36 | X6: 350 | Y6: =T6*15.42 -> 285.7326 | Z6: =Y6*1.08 -> 308.59121 | AA6: =C6*Z6 -> 2160.1385 | AB6: =(T6+9)*15.42 -> 424.5126 | AC6: =AB6*1.08 -> 458.47361 | AD6: =C6*AC6 -> 3209.3153 | AE6: =T6*22 -> 407.66 | AF6: =AE6*1.08 -> 440.2728 | AG6: =C6*AF6 -> 3081.9096 | AH6: =(T6+9)*22 -> 605.66 | AI6: =AH6*1.08 -> 654.1128 | AJ6: =C6*AI6 -> 4578.7896 | AK6: =Table1[[#This Row],[Total Selling Price / Unit (MVR)]]/Table1[[#This Row],[CNF / Unit (MVR)]] -> 3.7521441 | AL6: =Table1[[#This Row],[Total Selling Price / Unit (MVR)]]-(Table1[[#This Row],[GST 8% (MVR)]]+Table1[[#This Row],[Weighted max expense (MVR)]]) -> 186.11433 | AM6: =Table1[[#This Row],[Profit / Unit (MVR)]]*Table1[[#This Row],[Qty (NOS)]] -> 1302.8003 | AO6: Total Profit | AP6: =AP4-AP5 -> 66893.17
A7: Charcoal Pore Clay Cleansing Foam 180ml | B7: Cleansing & Peeling | C7: 7 | D7: 3.9 | E7: 27.3 | F7: =D7*22 -> 85.8 | G7: =SUM(F7*C7) -> 600.6 | H7: 119.02 | I7: 176.22 | J7: =L7-K7 -> 39.769733 | K7: =(F7/$G$92)*Costs!$B$23 -> 126.89693 | L7: =N7/1.08 -> 166.66667 | M7: =L7*0.08 -> 13.333333 | N7: 180 | O7: =Table1[[#This Row],[Total Selling Price / Unit (MVR)]]*Table1[[#This Row],[Qty (NOS)]] -> 1260 | Q7: 5.21 | R7: =Q7*22 -> 114.62 | S7: 119.02 | T7: 5.41 | U7: 3.9 | V7: 85.8 | W7: 176.22 | X7: 180 | Y7: =T7*15.42 -> 83.4222 | Z7: =Y7*1.08 -> 90.095976 | AA7: =C7*Z7 -> 630.67183 | AB7: =(T7+9)*15.42 -> 222.2022 | AC7: =AB7*1.08 -> 239.97838 | AD7: =C7*AC7 -> 1679.8486 | AE7: =T7*22 -> 119.02 | AF7: =AE7*1.08 -> 128.5416 | AG7: =C7*AF7 -> 899.7912 | AH7: =(T7+9)*22 -> 317.02 | AI7: =AH7*1.08 -> 342.3816 | AJ7: =C7*AI7 -> 2396.6712 | AK7: =Table1[[#This Row],[Total Selling Price / Unit (MVR)]]/Table1[[#This Row],[CNF / Unit (MVR)]] -> 2.0979021 | AL7: =Table1[[#This Row],[Total Selling Price / Unit (MVR)]]-(Table1[[#This Row],[GST 8% (MVR)]]+Table1[[#This Row],[Weighted max expense (MVR)]]) -> 39.769733 | AM7: =Table1[[#This Row],[Profit / Unit (MVR)]]*Table1[[#This Row],[Qty (NOS)]] -> 278.38813 | AO7: Shipment Target Sales 60% | AP7: =AP4*60% -> 81696.6
A8: FRUIT PEACH&APPLE MANGO CLEANSING FOAM 100ml | B8: Cleansing & Peeling | C8: 8 | D8: 2.02 | E8: 16.16 | F8: =D8*22 -> 44.44 | G8: =SUM(F8*C8) -> 355.52 | H8: 63.58 | I8: 161.7 | J8: =L8-K8 -> 54.644266 | K8: =(F8/$G$92)*Costs!$B$23 -> 65.726104 | L8: =N8/1.08 -> 120.37037 | M8: =L8*0.08 -> 9.6296296 | N8: 130 | O8: =Table1[[#This Row],[Total Selling Price / Unit (MVR)]]*Table1[[#This Row],[Qty (NOS)]] -> 1040 | Q8: 2.79 | R8: =Q8*22 -> 61.38 | S8: 63.58 | T8: 2.89 | U8: 2.02 | V8: 44.44 | W8: 161.7 | X8: 130 | Y8: =T8*15.42 -> 44.5638 | Z8: =Y8*1.08 -> 48.128904 | AA8: =C8*Z8 -> 385.03123 | AB8: =(T8+9)*15.42 -> 183.3438 | AC8: =AB8*1.08 -> 198.0113 | AD8: =C8*AC8 -> 1584.0904 | AE8: =T8*22 -> 63.58 | AF8: =AE8*1.08 -> 68.6664 | AG8: =C8*AF8 -> 549.3312 | AH8: =(T8+9)*22 -> 261.58 | AI8: =AH8*1.08 -> 282.5064 | AJ8: =C8*AI8 -> 2260.0512 | AK8: =Table1[[#This Row],[Total Selling Price / Unit (MVR)]]/Table1[[#This Row],[CNF / Unit (MVR)]] -> 2.9252925 | AL8: =Table1[[#This Row],[Total Selling Price / Unit (MVR)]]-(Table1[[#This Row],[GST 8% (MVR)]]+Table1[[#This Row],[Weighted max expense (MVR)]]) -> 54.644266 | AM8: =Table1[[#This Row],[Profit / Unit (MVR)]]*Table1[[#This Row],[Qty (NOS)]] -> 437.15413
A9: Glutathione Bubble Chewy Foam 200ml | B9: Cleansing & Peeling | C9: 4 | D9: 7.06 | E9: 28.24 | F9: =D9*22 -> 155.32 | G9: =SUM(F9*C9) -> 621.28 | H9: 487.52 | I9: 322.74 | J9: =L9-K9 -> 140.65438 | K9: =(F9/$G$92)*Costs!$B$23 -> 229.71599 | L9: =N9/1.08 -> 370.37037 | M9: =L9*0.08 -> 29.62963 | N9: 400 | O9: =Table1[[#This Row],[Total Selling Price / Unit (MVR)]]*Table1[[#This Row],[Qty (NOS)]] -> 1600 | Q9: 21.36 | R9: =Q9*22 -> 469.92 | S9: 487.52 | T9: 22.16 | U9: 7.06 | V9: 155.32 | W9: 322.74 | X9: 400 | Y9: =T9*15.42 -> 341.7072 | Z9: =Y9*1.08 -> 369.04378 | AA9: =C9*Z9 -> 1476.1751 | AB9: =(T9+9)*15.42 -> 480.4872 | AC9: =AB9*1.08 -> 518.92618 | AD9: =C9*AC9 -> 2075.7047 | AE9: =T9*22 -> 487.52 | AF9: =AE9*1.08 -> 526.5216 | AG9: =C9*AF9 -> 2106.0864 | AH9: =(T9+9)*22 -> 685.52 | AI9: =AH9*1.08 -> 740.3616 | AJ9: =C9*AI9 -> 2961.4464 | AK9: =Table1[[#This Row],[Total Selling Price / Unit (MVR)]]/Table1[[#This Row],[CNF / Unit (MVR)]] -> 2.5753284 | AL9: =Table1[[#This Row],[Total Selling Price / Unit (MVR)]]-(Table1[[#This Row],[GST 8% (MVR)]]+Table1[[#This Row],[Weighted max expense (MVR)]]) -> 140.65438 | AM9: =Table1[[#This Row],[Profit / Unit (MVR)]]*Table1[[#This Row],[Qty (NOS)]] -> 562.61753
A10: Glutinous Rice Clay 2in1 Pack Foam 120ml | B10: Cleansing & Peeling | C10: 4 | D10: 4.24 | E10: 16.96 | F10: =D10*22 -> 93.28 | G10: =SUM(F10*C10) -> 373.12 | H10: 407.66 | I10: 162.36 | J10: =L10-K10 -> 186.11433 | K10: =(F10/$G$92)*Costs!$B$23 -> 137.95974 | L10: =N10/1.08 -> 324.07407 | M10: =L10*0.08 -> 25.925926 | N10: 350 | O10: =Table1[[#This Row],[Total Selling Price / Unit (MVR)]]*Table1[[#This Row],[Qty (NOS)]] -> 1400 | Q10: 17.86 | R10: =Q10*22 -> 392.92 | S10: 407.66 | T10: 18.53 | U10: 4.24 | V10: 93.28 | W10: 162.36 | X10: 350 | Y10: =T10*15.42 -> 285.7326 | Z10: =Y10*1.08 -> 308.59121 | AA10: =C10*Z10 -> 1234.3648 | AB10: =(T10+9)*15.42 -> 424.5126 | AC10: =AB10*1.08 -> 458.47361 | AD10: =C10*AC10 -> 1833.8944 | AE10: =T10*22 -> 407.66 | AF10: =AE10*1.08 -> 440.2728 | AG10: =C10*AF10 -> 1761.0912 | AH10: =(T10+9)*22 -> 605.66 | AI10: =AH10*1.08 -> 654.1128 | AJ10: =C10*AI10 -> 2616.4512 | AK10: =Table1[[#This Row],[Total Selling Price / Unit (MVR)]]/Table1[[#This Row],[CNF / Unit (MVR)]] -> 3.7521441 | AL10: =Table1[[#This Row],[Total Selling Price / Unit (MVR)]]-(Table1[[#This Row],[GST 8% (MVR)]]+Table1[[#This Row],[Weighted max expense (MVR)]]) -> 186.11433 | AM10: =Table1[[#This Row],[Profit / Unit (MVR)]]*Table1[[#This Row],[Qty (NOS)]] -> 744.45732
A11: Lemon Brightening Cleansing Foam 180ml | B11: Cleansing & Peeling | C11: 4 | D11: 3.9 | E11: 15.6 | F11: =D11*22 -> 85.8 | G11: =SUM(F11*C11) -> 343.2 | H11: 119.02 | I11: 176.22 | J11: =L11-K11 -> 39.769733 | K11: =(F11/$G$92)*Costs!$B$23 -> 126.89693 | L11: =N11/1.08 -> 166.66667 | M11: =L11*0.08 -> 13.333333 | N11: 180 | O11: =Table1[[#This Row],[Total Selling Price / Unit (MVR)]]*Table1[[#This Row],[Qty (NOS)]] -> 720 | Q11: 5.21 | R11: =Q11*22 -> 114.62 | S11: 119.02 | T11: 5.41 | U11: 3.9 | V11: 85.8 | W11: 176.22 | X11: 180 | Y11: =T11*15.42 -> 83.4222 | Z11: =Y11*1.08 -> 90.095976 | AA11: =C11*Z11 -> 360.3839 | AB11: =(T11+9)*15.42 -> 222.2022 | AC11: =AB11*1.08 -> 239.97838 | AD11: =C11*AC11 -> 959.9135 | AE11: =T11*22 -> 119.02 | AF11: =AE11*1.08 -> 128.5416 | AG11: =C11*AF11 -> 514.1664 | AH11: =(T11+9)*22 -> 317.02 | AI11: =AH11*1.08 -> 342.3816 | AJ11: =C11*AI11 -> 1369.5264 | AK11: =Table1[[#This Row],[Total Selling Price / Unit (MVR)]]/Table1[[#This Row],[CNF / Unit (MVR)]] -> 2.0979021 | AL11: =Table1[[#This Row],[Total Selling Price / Unit (MVR)]]-(Table1[[#This Row],[GST 8% (MVR)]]+Table1[[#This Row],[Weighted max expense (MVR)]]) -> 39.769733 | AM11: =Table1[[#This Row],[Profit / Unit (MVR)]]*Table1[[#This Row],[Qty (NOS)]] -> 159.07893
A12: Panthenol Bubble Chewy Foam 200ml | B12: Cleansing & Peeling | C12: 4 | D12: 7.06 | E12: 28.24 | F12: =D12*22 -> 155.32 | G12: =SUM(F12*C12) -> 621.28 | H12: 487.52 | I12: 322.74 | J12: =L12-K12 -> 140.65438 | K12: =(F12/$G$92)*Costs!$B$23 -> 229.71599 | L12: =N12/1.08 -> 370.37037 | M12: =L12*0.08 -> 29.62963 | N12: 400 | O12: =Table1[[#This Row],[Total Selling Price / Unit (MVR)]]*Table1[[#This Row],[Qty (NOS)]] -> 1600 | Q12: 21.36 | R12: =Q12*22 -> 469.92 | S12: 487.52 | T12: 22.16 | U12: 7.06 | V12: 155.32 | W12: 322.74 | X12: 400 | Y12: =T12*15.42 -> 341.7072 | Z12: =Y12*1.08 -> 369.04378 | AA12: =C12*Z12 -> 1476.1751 | AB12: =(T12+9)*15.42 -> 480.4872 | AC12: =AB12*1.08 -> 518.92618 | AD12: =C12*AC12 -> 2075.7047 | AE12: =T12*22 -> 487.52 | AF12: =AE12*1.08 -> 526.5216 | AG12: =C12*AF12 -> 2106.0864 | AH12: =(T12+9)*22 -> 685.52 | AI12: =AH12*1.08 -> 740.3616 | AJ12: =C12*AI12 -> 2961.4464 | AK12: =Table1[[#This Row],[Total Selling Price / Unit (MVR)]]/Table1[[#This Row],[CNF / Unit (MVR)]] -> 2.5753284 | AL12: =Table1[[#This Row],[Total Selling Price / Unit (MVR)]]-(Table1[[#This Row],[GST 8% (MVR)]]+Table1[[#This Row],[Weighted max expense (MVR)]]) -> 140.65438 | AM12: =Table1[[#This Row],[Profit / Unit (MVR)]]*Table1[[#This Row],[Qty (NOS)]] -> 562.61753
A13: PDRN Bubble Chewy Foam 200ml | B13: Cleansing & Peeling | C13: 4 | D13: 7.06 | E13: 28.24 | F13: =D13*22 -> 155.32 | G13: =SUM(F13*C13) -> 621.28 | H13: 487.52 | I13: 322.74 | J13: =L13-K13 -> 140.65438 | K13: =(F13/$G$92)*Costs!$B$23 -> 229.71599 | L13: =N13/1.08 -> 370.37037 | M13: =L13*0.08 -> 29.62963 | N13: 400 | O13: =Table1[[#This Row],[Total Selling Price / Unit (MVR)]]*Table1[[#This Row],[Qty (NOS)]] -> 1600 | Q13: 21.36 | R13: =Q13*22 -> 469.92 | S13: 487.52 | T13: 22.16 | U13: 7.06 | V13: 155.32 | W13: 322.74 | X13: 400 | Y13: =T13*15.42 -> 341.7072 | Z13: =Y13*1.08 -> 369.04378 | AA13: =C13*Z13 -> 1476.1751 | AB13: =(T13+9)*15.42 -> 480.4872 | AC13: =AB13*1.08 -> 518.92618 | AD13: =C13*AC13 -> 2075.7047 | AE13: =T13*22 -> 487.52 | AF13: =AE13*1.08 -> 526.5216 | AG13: =C13*AF13 -> 2106.0864 | AH13: =(T13+9)*22 -> 685.52 | AI13: =AH13*1.08 -> 740.3616 | AJ13: =C13*AI13 -> 2961.4464 | AK13: =Table1[[#This Row],[Total Selling Price / Unit (MVR)]]/Table1[[#This Row],[CNF / Unit (MVR)]] -> 2.5753284 | AL13: =Table1[[#This Row],[Total Selling Price / Unit (MVR)]]-(Table1[[#This Row],[GST 8% (MVR)]]+Table1[[#This Row],[Weighted max expense (MVR)]]) -> 140.65438 | AM13: =Table1[[#This Row],[Profit / Unit (MVR)]]*Table1[[#This Row],[Qty (NOS)]] -> 562.61753
A14: Real Sensation Blemish Cleansing Foam 1+1 150ml x 2 | B14: Cleansing & Peeling | C14: 8 | D14: 6.84 | E14: 54.72 | F14: =D14*22 -> 150.48 | G14: =SUM(F14*C14) -> 1203.84 | H14: N/A | I14: 403.04 | J14: =L14-K14 -> 180.22008 | K14: =(F14/$G$92)*Costs!$B$23 -> 222.5577 | L14: =N14/1.08 -> 402.77778 | M14: =L14*0.08 -> 32.222222 | N14: 435 | O14: =Table1[[#This Row],[Total Selling Price / Unit (MVR)]]*Table1[[#This Row],[Qty (NOS)]] -> 3480 | Q14: 21.36 | R14: =Q14*22 -> 469.92 | S14: N/A | T14: 22.16 | U14: 6.84 | V14: 150.48 | W14: 403.04 | X14: 435 | Y14: =T14*15.42 -> 341.7072 | Z14: =Y14*1.08 -> 369.04378 | AA14: =C14*Z14 -> 2952.3502 | AB14: =(T14+9)*15.42 -> 480.4872 | AC14: =AB14*1.08 -> 518.92618 | AD14: =C14*AC14 -> 4151.4094 | AE14: =T14*22 -> 487.52 | AF14: =AE14*1.08 -> 526.5216 | AG14: =C14*AF14 -> 4212.1728 | AH14: =(T14+9)*22 -> 685.52 | AI14: =AH14*1.08 -> 740.3616 | AJ14: =C14*AI14 -> 5922.8928 | AK14: =Table1[[#This Row],[Total Selling Price / Unit (MVR)]]/Table1[[#This Row],[CNF / Unit (MVR)]] -> 2.8907496 | AL14: =Table1[[#This Row],[Total Selling Price / Unit (MVR)]]-(Table1[[#This Row],[GST 8% (MVR)]]+Table1[[#This Row],[Weighted max expense (MVR)]]) -> 180.22008 | AM14: =Table1[[#This Row],[Profit / Unit (MVR)]]*Table1[[#This Row],[Qty (NOS)]] -> 1441.7606
A15: Real Sensation Pore Cleansing Foam 1+1 150ml x 2 | B15: Cleansing & Peeling | C15: 6 | D15: 6.84 | E15: 41.04 | F15: =D15*22 -> 150.48 | G15: =SUM(F15*C15) -> 902.88 | H15: N/A | I15: 403.04 | J15: =L15-K15 -> 180.22008 | K15: =(F15/$G$92)*Costs!$B$23 -> 222.5577 | L15: =N15/1.08 -> 402.77778 | M15: =L15*0.08 -> 32.222222 | N15: 435 | O15: =Table1[[#This Row],[Total Selling Price / Unit (MVR)]]*Table1[[#This Row],[Qty (NOS)]] -> 2610 | Q15: 21.36 | R15: =Q15*22 -> 469.92 | S15: N/A | T15: 22.16 | U15: 6.84 | V15: 150.48 | W15: 403.04 | X15: 435 | Y15: =T15*15.42 -> 341.7072 | Z15: =Y15*1.08 -> 369.04378 | AA15: =C15*Z15 -> 2214.2627 | AB15: =(T15+9)*15.42 -> 480.4872 | AC15: =AB15*1.08 -> 518.92618 | AD15: =C15*AC15 -> 3113.5571 | AE15: =T15*22 -> 487.52 | AF15: =AE15*1.08 -> 526.5216 | AG15: =C15*AF15 -> 3159.1296 | AH15: =(T15+9)*22 -> 685.52 | AI15: =AH15*1.08 -> 740.3616 | AJ15: =C15*AI15 -> 4442.1696 | AK15: =Table1[[#This Row],[Total Selling Price / Unit (MVR)]]/Table1[[#This Row],[CNF / Unit (MVR)]] -> 2.8907496 | AL15: =Table1[[#This Row],[Total Selling Price / Unit (MVR)]]-(Table1[[#This Row],[GST 8% (MVR)]]+Table1[[#This Row],[Weighted max expense (MVR)]]) -> 180.22008 | AM15: =Table1[[#This Row],[Profit / Unit (MVR)]]*Table1[[#This Row],[Qty (NOS)]] -> 1081.3205
A16: Retinol Bubble Chewy Foam 200ml | B16: Cleansing & Peeling | C16: 4 | D16: 7.06 | E16: 28.24 | F16: =D16*22 -> 155.32 | G16: =SUM(F16*C16) -> 621.28 | H16: 487.52 | I16: 322.74 | J16: =L16-K16 -> 140.65438 | K16: =(F16/$G$92)*Costs!$B$23 -> 229.71599 | L16: =N16/1.08 -> 370.37037 | M16: =L16*0.08 -> 29.62963 | N16: 400 | O16: =Table1[[#This Row],[Total Selling Price / Unit (MVR)]]*Table1[[#This Row],[Qty (NOS)]] -> 1600 | Q16: 21.36 | R16: =Q16*22 -> 469.92 | S16: 487.52 | T16: 22.16 | U16: 7.06 | V16: 155.32 | W16: 322.74 | X16: 400 | Y16: =T16*15.42 -> 341.7072 | Z16: =Y16*1.08 -> 369.04378 | AA16: =C16*Z16 -> 1476.1751 | AB16: =(T16+9)*15.42 -> 480.4872 | AC16: =AB16*1.08 -> 518.92618 | AD16: =C16*AC16 -> 2075.7047 | AE16: =T16*22 -> 487.52 | AF16: =AE16*1.08 -> 526.5216 | AG16: =C16*AF16 -> 2106.0864 | AH16: =(T16+9)*22 -> 685.52 | AI16: =AH16*1.08 -> 740.3616 | AJ16: =C16*AI16 -> 2961.4464 | AK16: =Table1[[#This Row],[Total Selling Price / Unit (MVR)]]/Table1[[#This Row],[CNF / Unit (MVR)]] -> 2.5753284 | AL16: =Table1[[#This Row],[Total Selling Price / Unit (MVR)]]-(Table1[[#This Row],[GST 8% (MVR)]]+Table1[[#This Row],[Weighted max expense (MVR)]]) -> 140.65438 | AM16: =Table1[[#This Row],[Profit / Unit (MVR)]]*Table1[[#This Row],[Qty (NOS)]] -> 562.61753
A17: Soybean Clay 2in1 Pack Foam 120ml | B17: Cleansing & Peeling | C17: 4 | D17: 4.24 | E17: 16.96 | F17: =D17*22 -> 93.28 | G17: =SUM(F17*C17) -> 373.12 | H17: 407.66 | I17: 162.36 | J17: =L17-K17 -> 186.11433 | K17: =(F17/$G$92)*Costs!$B$23 -> 137.95974 | L17: =N17/1.08 -> 324.07407 | M17: =L17*0.08 -> 25.925926 | N17: 350 | O17: =Table1[[#This Row],[Total Selling Price / Unit (MVR)]]*Table1[[#This Row],[Qty (NOS)]] -> 1400 | Q17: 17.86 | R17: =Q17*22 -> 392.92 | S17: 407.66 | T17: 18.53 | U17: 4.24 | V17: 93.28 | W17: 162.36 | X17: 350 | Y17: =T17*15.42 -> 285.7326 | Z17: =Y17*1.08 -> 308.59121 | AA17: =C17*Z17 -> 1234.3648 | AB17: =(T17+9)*15.42 -> 424.5126 | AC17: =AB17*1.08 -> 458.47361 | AD17: =C17*AC17 -> 1833.8944 | AE17: =T17*22 -> 407.66 | AF17: =AE17*1.08 -> 440.2728 | AG17: =C17*AF17 -> 1761.0912 | AH17: =(T17+9)*22 -> 605.66 | AI17: =AH17*1.08 -> 654.1128 | AJ17: =C17*AI17 -> 2616.4512 | AK17: =Table1[[#This Row],[Total Selling Price / Unit (MVR)]]/Table1[[#This Row],[CNF / Unit (MVR)]] -> 3.7521441 | AL17: =Table1[[#This Row],[Total Selling Price / Unit (MVR)]]-(Table1[[#This Row],[GST 8% (MVR)]]+Table1[[#This Row],[Weighted max expense (MVR)]]) -> 186.11433 | AM17: =Table1[[#This Row],[Profit / Unit (MVR)]]*Table1[[#This Row],[Qty (NOS)]] -> 744.45732
A18: Ssook/Mugwort Clay 2in1 Pack Foam 120ml | B18: Cleansing & Peeling | C18: 4 | D18: 4.24 | E18: 16.96 | F18: =D18*22 -> 93.28 | G18: =SUM(F18*C18) -> 373.12 | H18: 407.66 | I18: 162.36 | J18: =L18-K18 -> 186.11433 | K18: =(F18/$G$92)*Costs!$B$23 -> 137.95974 | L18: =N18/1.08 -> 324.07407 | M18: =L18*0.08 -> 25.925926 | N18: 350 | O18: =Table1[[#This Row],[Total Selling Price / Unit (MVR)]]*Table1[[#This Row],[Qty (NOS)]] -> 1400 | Q18: 17.86 | R18: =Q18*22 -> 392.92 | S18: 407.66 | T18: 18.53 | U18: 4.24 | V18: 93.28 | W18: 162.36 | X18: 350 | Y18: =T18*15.42 -> 285.7326 | Z18: =Y18*1.08 -> 308.59121 | AA18: =C18*Z18 -> 1234.3648 | AB18: =(T18+9)*15.42 -> 424.5126 | AC18: =AB18*1.08 -> 458.47361 | AD18: =C18*AC18 -> 1833.8944 | AE18: =T18*22 -> 407.66 | AF18: =AE18*1.08 -> 440.2728 | AG18: =C18*AF18 -> 1761.0912 | AH18: =(T18+9)*22 -> 605.66 | AI18: =AH18*1.08 -> 654.1128 | AJ18: =C18*AI18 -> 2616.4512 | AK18: =Table1[[#This Row],[Total Selling Price / Unit (MVR)]]/Table1[[#This Row],[CNF / Unit (MVR)]] -> 3.7521441 | AL18: =Table1[[#This Row],[Total Selling Price / Unit (MVR)]]-(Table1[[#This Row],[GST 8% (MVR)]]+Table1[[#This Row],[Weighted max expense (MVR)]]) -> 186.11433 | AM18: =Table1[[#This Row],[Profit / Unit (MVR)]]*Table1[[#This Row],[Qty (NOS)]] -> 744.45732
A19: Vitamin C + Turmeric Bubble Chewy Foam 200ml | B19: Cleansing & Peeling | C19: 4 | D19: 7.06 | E19: 28.24 | F19: =D19*22 -> 155.32 | G19: =SUM(F19*C19) -> 621.28 | H19: 487.52 | I19: 322.74 | J19: =L19-K19 -> 140.65438 | K19: =(F19/$G$92)*Costs!$B$23 -> 229.71599 | L19: =N19/1.08 -> 370.37037 | M19: =L19*0.08 -> 29.62963 | N19: 400 | O19: =Table1[[#This Row],[Total Selling Price / Unit (MVR)]]*Table1[[#This Row],[Qty (NOS)]] -> 1600 | Q19: 21.36 | R19: =Q19*22 -> 469.92 | S19: 487.52 | T19: 22.16 | U19: 7.06 | V19: 155.32 | W19: 322.74 | X19: 400 | Y19: =T19*15.42 -> 341.7072 | Z19: =Y19*1.08 -> 369.04378 | AA19: =C19*Z19 -> 1476.1751 | AB19: =(T19+9)*15.42 -> 480.4872 | AC19: =AB19*1.08 -> 518.92618 | AD19: =C19*AC19 -> 2075.7047 | AE19: =T19*22 -> 487.52 | AF19: =AE19*1.08 -> 526.5216 | AG19: =C19*AF19 -> 2106.0864 | AH19: =(T19+9)*22 -> 685.52 | AI19: =AH19*1.08 -> 740.3616 | AJ19: =C19*AI19 -> 2961.4464 | AK19: =Table1[[#This Row],[Total Selling Price / Unit (MVR)]]/Table1[[#This Row],[CNF / Unit (MVR)]] -> 2.5753284 | AL19: =Table1[[#This Row],[Total Selling Price / Unit (MVR)]]-(Table1[[#This Row],[GST 8% (MVR)]]+Table1[[#This Row],[Weighted max expense (MVR)]]) -> 140.65438 | AM19: =Table1[[#This Row],[Profit / Unit (MVR)]]*Table1[[#This Row],[Qty (NOS)]] -> 562.61753
A20: Collagen + Green Tea Moisture Cream 70ml | B20: Creams & Moisturizers | C20: 4 | D20: 4.57 | E20: 18.28 | F20: =D20*22 -> 100.54 | G20: =SUM(F20*C20) -> 402.16 | H20: 407.66 | I20: 275 | J20: =L20-K20 -> 156.85838 | K20: =(F20/$G$92)*Costs!$B$23 -> 148.69718 | L20: =N20/1.08 -> 305.55556 | M20: =L20*0.08 -> 24.444444 | N20: 330 | O20: =Table1[[#This Row],[Total Selling Price / Unit (MVR)]]*Table1[[#This Row],[Qty (NOS)]] -> 1320 | Q20: 7.14 | R20: =Q20*22 -> 157.08 | S20: 407.66 | T20: 18.53 | U20: 4.57 | V20: 100.54 | W20: 275 | X20: 330 | Y20: =T20*15.42 -> 285.7326 | Z20: =Y20*1.08 -> 308.59121 | AA20: =C20*Z20 -> 1234.3648 | AB20: =(T20+9)*15.42 -> 424.5126 | AC20: =AB20*1.08 -> 458.47361 | AD20: =C20*AC20 -> 1833.8944 | AE20: =T20*22 -> 407.66 | AF20: =AE20*1.08 -> 440.2728 | AG20: =C20*AF20 -> 1761.0912 | AH20: =(T20+9)*22 -> 605.66 | AI20: =AH20*1.08 -> 654.1128 | AJ20: =C20*AI20 -> 2616.4512 | AK20: =Table1[[#This Row],[Total Selling Price / Unit (MVR)]]/Table1[[#This Row],[CNF / Unit (MVR)]] -> 3.2822757 | AL20: =Table1[[#This Row],[Total Selling Price / Unit (MVR)]]-(Table1[[#This Row],[GST 8% (MVR)]]+Table1[[#This Row],[Weighted max expense (MVR)]]) -> 156.85838 | AM20: =Table1[[#This Row],[Profit / Unit (MVR)]]*Table1[[#This Row],[Qty (NOS)]] -> 627.43352
A21: Dr. AQUA CURE CREAM 70ml | B21: Creams & Moisturizers | C21: 4 | D21: 4.66 | E21: 18.64 | F21: =D21*22 -> 102.52 | G21: =SUM(F21*C21) -> 410.08 | H21: 211.86 | I21: 242.44 | J21: =L21-K21 -> 56.707767 | K21: =(F21/$G$92)*Costs!$B$23 -> 151.62557 | L21: =N21/1.08 -> 208.33333 | M21: =L21*0.08 -> 16.666667 | N21: 225 | O21: =Table1[[#This Row],[Total Selling Price / Unit (MVR)]]*Table1[[#This Row],[Qty (NOS)]] -> 900 | Q21: 17.86 | R21: =Q21*22 -> 392.92 | S21: 211.86 | T21: 9.63 | U21: 4.66 | V21: 102.52 | W21: 242.44 | X21: 225 | Y21: =T21*15.42 -> 148.4946 | Z21: =Y21*1.08 -> 160.37417 | AA21: =C21*Z21 -> 641.49667 | AB21: =(T21+9)*15.42 -> 287.2746 | AC21: =AB21*1.08 -> 310.25657 | AD21: =C21*AC21 -> 1241.0263 | AE21: =T21*22 -> 211.86 | AF21: =AE21*1.08 -> 228.8088 | AG21: =C21*AF21 -> 915.2352 | AH21: =(T21+9)*22 -> 409.86 | AI21: =AH21*1.08 -> 442.6488 | AJ21: =C21*AI21 -> 1770.5952 | AK21: =Table1[[#This Row],[Total Selling Price / Unit (MVR)]]/Table1[[#This Row],[CNF / Unit (MVR)]] -> 2.1946937 | AL21: =Table1[[#This Row],[Total Selling Price / Unit (MVR)]]-(Table1[[#This Row],[GST 8% (MVR)]]+Table1[[#This Row],[Weighted max expense (MVR)]]) -> 56.707767 | AM21: =Table1[[#This Row],[Profit / Unit (MVR)]]*Table1[[#This Row],[Qty (NOS)]] -> 226.83107
A22: Dr. Madecassoside Cure Cream 70ml | B22: Creams & Moisturizers | C22: 7 | D22: 4.66 | E22: 32.62 | F22: =D22*22 -> 102.52 | G22: =SUM(F22*C22) -> 717.64 | H22: 211.86 | I22: 242.44 | J22: =L22-K22 -> 56.707767 | K22: =(F22/$G$92)*Costs!$B$23 -> 151.62557 | L22: =N22/1.08 -> 208.33333 | M22: =L22*0.08 -> 16.666667 | N22: 225 | O22: =Table1[[#This Row],[Total Selling Price / Unit (MVR)]]*Table1[[#This Row],[Qty (NOS)]] -> 1575 | Q22: 17.86 | R22: =Q22*22 -> 392.92 | S22: 211.86 | T22: 9.63 | U22: 4.66 | V22: 102.52 | W22: 242.44 | X22: 225 | Y22: =T22*15.42 -> 148.4946 | Z22: =Y22*1.08 -> 160.37417 | AA22: =C22*Z22 -> 1122.6192 | AB22: =(T22+9)*15.42 -> 287.2746 | AC22: =AB22*1.08 -> 310.25657 | AD22: =C22*AC22 -> 2171.796 | AE22: =T22*22 -> 211.86 | AF22: =AE22*1.08 -> 228.8088 | AG22: =C22*AF22 -> 1601.6616 | AH22: =(T22+9)*22 -> 409.86 | AI22: =AH22*1.08 -> 442.6488 | AJ22: =C22*AI22 -> 3098.5416 | AK22: =Table1[[#This Row],[Total Selling Price / Unit (MVR)]]/Table1[[#This Row],[CNF / Unit (MVR)]] -> 2.1946937 | AL22: =Table1[[#This Row],[Total Selling Price / Unit (MVR)]]-(Table1[[#This Row],[GST 8% (MVR)]]+Table1[[#This Row],[Weighted max expense (MVR)]]) -> 56.707767 | AM22: =Table1[[#This Row],[Profit / Unit (MVR)]]*Table1[[#This Row],[Qty (NOS)]] -> 396.95437
A23: Dr. Peptide Cure Cream 70ml | B23: Creams & Moisturizers | C23: 4 | D23: 4.66 | E23: 18.64 | F23: =D23*22 -> 102.52 | G23: =SUM(F23*C23) -> 410.08 | H23: 211.86 | I23: 242.44 | J23: =L23-K23 -> 56.707767 | K23: =(F23/$G$92)*Costs!$B$23 -> 151.62557 | L23: =N23/1.08 -> 208.33333 | M23: =L23*0.08 -> 16.666667 | N23: 225 | O23: =Table1[[#This Row],[Total Selling Price / Unit (MVR)]]*Table1[[#This Row],[Qty (NOS)]] -> 900 | Q23: 17.86 | R23: =Q23*22 -> 392.92 | S23: 211.86 | T23: 9.63 | U23: 4.66 | V23: 102.52 | W23: 242.44 | X23: 225 | Y23: =T23*15.42 -> 148.4946 | Z23: =Y23*1.08 -> 160.37417 | AA23: =C23*Z23 -> 641.49667 | AB23: =(T23+9)*15.42 -> 287.2746 | AC23: =AB23*1.08 -> 310.25657 | AD23: =C23*AC23 -> 1241.0263 | AE23: =T23*22 -> 211.86 | AF23: =AE23*1.08 -> 228.8088 | AG23: =C23*AF23 -> 915.2352 | AH23: =(T23+9)*22 -> 409.86 | AI23: =AH23*1.08 -> 442.6488 | AJ23: =C23*AI23 -> 1770.5952 | AK23: =Table1[[#This Row],[Total Selling Price / Unit (MVR)]]/Table1[[#This Row],[CNF / Unit (MVR)]] -> 2.1946937 | AL23: =Table1[[#This Row],[Total Selling Price / Unit (MVR)]]-(Table1[[#This Row],[GST 8% (MVR)]]+Table1[[#This Row],[Weighted max expense (MVR)]]) -> 56.707767 | AM23: =Table1[[#This Row],[Profit / Unit (MVR)]]*Table1[[#This Row],[Qty (NOS)]] -> 226.83107
A24: Dr. Vitamin C Cure Cream 70ml | B24: Creams & Moisturizers | C24: 4 | D24: 4.66 | E24: 18.64 | F24: =D24*22 -> 102.52 | G24: =SUM(F24*C24) -> 410.08 | H24: 211.86 | I24: 242.44 | J24: =L24-K24 -> 56.707767 | K24: =(F24/$G$92)*Costs!$B$23 -> 151.62557 | L24: =N24/1.08 -> 208.33333 | M24: =L24*0.08 -> 16.666667 | N24: 225 | O24: =Table1[[#This Row],[Total Selling Price / Unit (MVR)]]*Table1[[#This Row],[Qty (NOS)]] -> 900 | Q24: 17.86 | R24: =Q24*22 -> 392.92 | S24: 211.86 | T24: 9.63 | U24: 4.66 | V24: 102.52 | W24: 242.44 | X24: 225 | Y24: =T24*15.42 -> 148.4946 | Z24: =Y24*1.08 -> 160.37417 | AA24: =C24*Z24 -> 641.49667 | AB24: =(T24+9)*15.42 -> 287.2746 | AC24: =AB24*1.08 -> 310.25657 | AD24: =C24*AC24 -> 1241.0263 | AE24: =T24*22 -> 211.86 | AF24: =AE24*1.08 -> 228.8088 | AG24: =C24*AF24 -> 915.2352 | AH24: =(T24+9)*22 -> 409.86 | AI24: =AH24*1.08 -> 442.6488 | AJ24: =C24*AI24 -> 1770.5952 | AK24: =Table1[[#This Row],[Total Selling Price / Unit (MVR)]]/Table1[[#This Row],[CNF / Unit (MVR)]] -> 2.1946937 | AL24: =Table1[[#This Row],[Total Selling Price / Unit (MVR)]]-(Table1[[#This Row],[GST 8% (MVR)]]+Table1[[#This Row],[Weighted max expense (MVR)]]) -> 56.707767 | AM24: =Table1[[#This Row],[Profit / Unit (MVR)]]*Table1[[#This Row],[Qty (NOS)]] -> 226.83107
A25: Gold Caviar Ampoule Cream 70ml | B25: Creams & Moisturizers | C25: 3 | D25: 4.82 | E25: 14.46 | F25: =D25*22 -> 106.04 | G25: =SUM(F25*C25) -> 318.12 | H25: 407.66 | I25: 272.8 | J25: =L25-K25 -> 167.24248 | K25: =(F25/$G$92)*Costs!$B$23 -> 156.83159 | L25: =N25/1.08 -> 324.07407 | M25: =L25*0.08 -> 25.925926 | N25: 350 | O25: =Table1[[#This Row],[Total Selling Price / Unit (MVR)]]*Table1[[#This Row],[Qty (NOS)]] -> 1050 | Q25: 17.86 | R25: =Q25*22 -> 392.92 | S25: 407.66 | T25: 18.53 | U25: 4.82 | V25: 106.04 | W25: 272.8 | X25: 350 | Y25: =T25*15.42 -> 285.7326 | Z25: =Y25*1.08 -> 308.59121 | AA25: =C25*Z25 -> 925.77362 | AB25: =(T25+9)*15.42 -> 424.5126 | AC25: =AB25*1.08 -> 458.47361 | AD25: =C25*AC25 -> 1375.4208 | AE25: =T25*22 -> 407.66 | AF25: =AE25*1.08 -> 440.2728 | AG25: =C25*AF25 -> 1320.8184 | AH25: =(T25+9)*22 -> 605.66 | AI25: =AH25*1.08 -> 654.1128 | AJ25: =C25*AI25 -> 1962.3384 | AK25: =Table1[[#This Row],[Total Selling Price / Unit (MVR)]]/Table1[[#This Row],[CNF / Unit (MVR)]] -> 3.3006413 | AL25: =Table1[[#This Row],[Total Selling Price / Unit (MVR)]]-(Table1[[#This Row],[GST 8% (MVR)]]+Table1[[#This Row],[Weighted max expense (MVR)]]) -> 167.24248 | AM25: =Table1[[#This Row],[Profit / Unit (MVR)]]*Table1[[#This Row],[Qty (NOS)]] -> 501.72744
A26: Real Sensation Blemish Cream 55g | B26: Creams & Moisturizers | C26: 4 | D26: 11 | E26: 44 | F26: =D26*22 -> 242 | G26: =SUM(F26*C26) -> 968 | H26: 1613.92 | I26: 436.48 | J26: =L26-K26 -> 86.530016 | K26: =(F26/$G$92)*Costs!$B$23 -> 357.91443 | L26: =N26/1.08 -> 444.44444 | M26: =L26*0.08 -> 35.555556 | N26: 480 | O26: =Table1[[#This Row],[Total Selling Price / Unit (MVR)]]*Table1[[#This Row],[Qty (NOS)]] -> 1920 | Q26: 70.71 | R26: =Q26*22 -> 1555.62 | S26: 1613.92 | T26: 73.36 | U26: 11 | V26: 242 | W26: 436.48 | X26: 480 | Y26: =T26*15.42 -> 1131.2112 | Z26: =Y26*1.08 -> 1221.7081 | AA26: =C26*Z26 -> 4886.8324 | AB26: =(T26+9)*15.42 -> 1269.9912 | AC26: =AB26*1.08 -> 1371.5905 | AD26: =C26*AC26 -> 5486.362 | AE26: =T26*22 -> 1613.92 | AF26: =AE26*1.08 -> 1743.0336 | AG26: =C26*AF26 -> 6972.1344 | AH26: =(T26+9)*22 -> 1811.92 | AI26: =AH26*1.08 -> 1956.8736 | AJ26: =C26*AI26 -> 7827.4944 | AK26: =Table1[[#This Row],[Total Selling Price / Unit (MVR)]]/Table1[[#This Row],[CNF / Unit (MVR)]] -> 1.9834711 | AL26: =Table1[[#This Row],[Total Selling Price / Unit (MVR)]]-(Table1[[#This Row],[GST 8% (MVR)]]+Table1[[#This Row],[Weighted max expense (MVR)]]) -> 86.530016 | AM26: =Table1[[#This Row],[Profit / Unit (MVR)]]*Table1[[#This Row],[Qty (NOS)]] -> 346.12007
A27: Real Sensation Pore Cream 55g | B27: Creams & Moisturizers | C27: 4 | D27: 11 | E27: 44 | F27: =D27*22 -> 242 | G27: =SUM(F27*C27) -> 968 | H27: 1613.92 | I27: 436.48 | J27: =L27-K27 -> 86.530016 | K27: =(F27/$G$92)*Costs!$B$23 -> 357.91443 | L27: =N27/1.08 -> 444.44444 | M27: =L27*0.08 -> 35.555556 | N27: 480 | O27: =Table1[[#This Row],[Total Selling Price / Unit (MVR)]]*Table1[[#This Row],[Qty (NOS)]] -> 1920 | Q27: 70.71 | R27: =Q27*22 -> 1555.62 | S27: 1613.92 | T27: 73.36 | U27: 11 | V27: 242 | W27: 436.48 | X27: 480 | Y27: =T27*15.42 -> 1131.2112 | Z27: =Y27*1.08 -> 1221.7081 | AA27: =C27*Z27 -> 4886.8324 | AB27: =(T27+9)*15.42 -> 1269.9912 | AC27: =AB27*1.08 -> 1371.5905 | AD27: =C27*AC27 -> 5486.362 | AE27: =T27*22 -> 1613.92 | AF27: =AE27*1.08 -> 1743.0336 | AG27: =C27*AF27 -> 6972.1344 | AH27: =(T27+9)*22 -> 1811.92 | AI27: =AH27*1.08 -> 1956.8736 | AJ27: =C27*AI27 -> 7827.4944 | AK27: =Table1[[#This Row],[Total Selling Price / Unit (MVR)]]/Table1[[#This Row],[CNF / Unit (MVR)]] -> 1.9834711 | AL27: =Table1[[#This Row],[Total Selling Price / Unit (MVR)]]-(Table1[[#This Row],[GST 8% (MVR)]]+Table1[[#This Row],[Weighted max expense (MVR)]]) -> 86.530016 | AM27: =Table1[[#This Row],[Profit / Unit (MVR)]]*Table1[[#This Row],[Qty (NOS)]] -> 346.12007
... A29: Wrinkle Collagen Ampoule Cream 70ml | B29: Creams & Moisturizers | C29: 4 | D29: 4.82 | E29: 19.28 | F29: =D29*22 -> 106.04 | G29: =SUM(F29*C29) -> 424.16 | H29: 407.66 | I29: 272.8 | J29: =L29-K29 -> 157.98322 | K29: =(F29/$G$92)*Costs!$B$23 -> 156.83159 | L29: =N29/1.08 -> 314.81481 | M29: =L29*0.08 -> 25.185185 | N29: 340 | O29: =Table1[[#This Row],[Total Selling Price / Unit (MVR)]]*Table1[[#This Row],[Qty (NOS)]] -> 1360 | Q29: 17.86 | R29: =Q29*22 -> 392.92 | S29: 407.66 | T29: 18.53 | U29: 4.82 | V29: 106.04 | W29: 272.8 | X29: 340 | Y29: =T29*15.42 -> 285.7326 | Z29: =Y29*1.08 -> 308.59121 | AA29: =C29*Z29 -> 1234.3648 | AB29: =(T29+9)*15.42 -> 424.5126 | AC29: =AB29*1.08 -> 458.47361 | AD29: =C29*AC29 -> 1833.8944 | AE29: =T29*22 -> 407.66 | AF29: =AE29*1.08 -> 440.2728 | AG29: =C29*AF29 -> 1761.0912 | AH29: =(T29+9)*22 -> 605.66 | AI29: =AH29*1.08 -> 654.1128 | AJ29: =C29*AI29 -> 2616.4512 | AK29: =Table1[[#This Row],[Total Selling Price / Unit (MVR)]]/Table1[[#This Row],[CNF / Unit (MVR)]] -> 3.2063372 | AL29: =Table1[[#This Row],[Total Selling Price / Unit (MVR)]]-(Table1[[#This Row],[GST 8% (MVR)]]+Table1[[#This Row],[Weighted max expense (MVR)]]) -> 157.98322 | AM29: =Table1[[#This Row],[Profit / Unit (MVR)]]*Table1[[#This Row],[Qty (NOS)]] -> 631.93288
A30: YUJA DERMA CREAM 50ml | B30: Creams & Moisturizers | C30: 4 | D30: 5.84 | E30: 23.36 | F30: =D30*22 -> 128.48 | G30: =SUM(F30*C30) -> 513.92 | H30: N/A | I30: 240.68 | J30: =L30-K30 -> 32.202199 | K30: =(F30/$G$92)*Costs!$B$23 -> 190.02002 | L30: =N30/1.08 -> 222.22222 | M30: =L30*0.08 -> 17.777778 | N30: 240 | O30: =Table1[[#This Row],[Total Selling Price / Unit (MVR)]]*Table1[[#This Row],[Qty (NOS)]] -> 960 | Q30: 55.71 | R30: =Q30*22 -> 1225.62 | S30: N/A | T30: 57.8 | U30: 5.84 | V30: 128.48 | W30: 240.68 | X30: 240 | Y30: =T30*15.42 -> 891.276 | Z30: =Y30*1.08 -> 962.57808 | AA30: =C30*Z30 -> 3850.3123 | AB30: =(T30+9)*15.42 -> 1030.056 | AC30: =AB30*1.08 -> 1112.4605 | AD30: =C30*AC30 -> 4449.8419 | AE30: =T30*22 -> 1271.6 | AF30: =AE30*1.08 -> 1373.328 | AG30: =C30*AF30 -> 5493.312 | AH30: =(T30+9)*22 -> 1469.6 | AI30: =AH30*1.08 -> 1587.168 | AJ30: =C30*AI30 -> 6348.672 | AK30: =Table1[[#This Row],[Total Selling Price / Unit (MVR)]]/Table1[[#This Row],[CNF / Unit (MVR)]] -> 1.867995 | AL30: =Table1[[#This Row],[Total Selling Price / Unit (MVR)]]-(Table1[[#This Row],[GST 8% (MVR)]]+Table1[[#This Row],[Weighted max expense (MVR)]]) -> 32.202199 | AM30: =Table1[[#This Row],[Profit / Unit (MVR)]]*Table1[[#This Row],[Qty (NOS)]] -> 128.80879
A31: YUJA DERMA CREAM 50ml | B31: Creams & Moisturizers | C31: 4 | D31: 5.84 | E31: 23.36 | F31: =D31*22 -> 128.48 | G31: =SUM(F31*C31) -> 513.92 | H31: N/A | I31: 240.68 | J31: =L31-K31 -> 32.202199 | K31: =(F31/$G$92)*Costs!$B$23 -> 190.02002 | L31: =N31/1.08 -> 222.22222 | M31: =L31*0.08 -> 17.777778 | N31: 240 | O31: =Table1[[#This Row],[Total Selling Price / Unit (MVR)]]*Table1[[#This Row],[Qty (NOS)]] -> 960 | Q31: 55.71 | R31: =Q31*22 -> 1225.62 | S31: N/A | T31: 57.8 | U31: 5.84 | V31: 128.48 | W31: 240.68 | X31: 240 | Y31: =T31*15.42 -> 891.276 | Z31: =Y31*1.08 -> 962.57808 | AA31: =C31*Z31 -> 3850.3123 | AB31: =(T31+9)*15.42 -> 1030.056 | AC31: =AB31*1.08 -> 1112.4605 | AD31: =C31*AC31 -> 4449.8419 | AE31: =T31*22 -> 1271.6 | AF31: =AE31*1.08 -> 1373.328 | AG31: =C31*AF31 -> 5493.312 | AH31: =(T31+9)*22 -> 1469.6 | AI31: =AH31*1.08 -> 1587.168 | AJ31: =C31*AI31 -> 6348.672 | AK31: =Table1[[#This Row],[Total Selling Price / Unit (MVR)]]/Table1[[#This Row],[CNF / Unit (MVR)]] -> 1.867995 | AL31: =Table1[[#This Row],[Total Selling Price / Unit (MVR)]]-(Table1[[#This Row],[GST 8% (MVR)]]+Table1[[#This Row],[Weighted max expense (MVR)]]) -> 32.202199 | AM31: =Table1[[#This Row],[Profit / Unit (MVR)]]*Table1[[#This Row],[Qty (NOS)]] -> 128.80879
A32: Black Snail Eye Cream EX 40ml | B32: Eye Care | C32: 4 | D32: 1.96 | E32: 7.84 | F32: =D32*22 -> 43.12 | G32: =SUM(F32*C32) -> 172.48 | H32: 407.66 | I32: 134.42 | J32: =L32-K32 -> 241.78171 | K32: =(F32/$G$92)*Costs!$B$23 -> 63.773844 | L32: =N32/1.08 -> 305.55556 | M32: =L32*0.08 -> 24.444444 | N32: 330 | O32: =Table1[[#This Row],[Total Selling Price / Unit (MVR)]]*Table1[[#This Row],[Qty (NOS)]] -> 1320 | Q32: 17.86 | R32: =Q32*22 -> 392.92 | S32: 407.66 | T32: 18.53 | U32: 1.96 | V32: 43.12 | W32: 134.42 | X32: 330 | Y32: =T32*15.42 -> 285.7326 | Z32: =Y32*1.08 -> 308.59121 | AA32: =C32*Z32 -> 1234.3648 | AB32: =(T32+9)*15.42 -> 424.5126 | AC32: =AB32*1.08 -> 458.47361 | AD32: =C32*AC32 -> 1833.8944 | AE32: =T32*22 -> 407.66 | AF32: =AE32*1.08 -> 440.2728 | AG32: =C32*AF32 -> 1761.0912 | AH32: =(T32+9)*22 -> 605.66 | AI32: =AH32*1.08 -> 654.1128 | AJ32: =C32*AI32 -> 2616.4512 | AK32: =Table1[[#This Row],[Total Selling Price / Unit (MVR)]]/Table1[[#This Row],[CNF / Unit (MVR)]] -> 7.6530612 | AL32: =Table1[[#This Row],[Total Selling Price / Unit (MVR)]]-(Table1[[#This Row],[GST 8% (MVR)]]+Table1[[#This Row],[Weighted max expense (MVR)]]) -> 241.78171 | AM32: =Table1[[#This Row],[Profit / Unit (MVR)]]*Table1[[#This Row],[Qty (NOS)]] -> 967.12685
A33: Collagen Hydrogel Eye Patch 90g / 60 sheets | B33: Eye Care | C33: 4 | D33: 6.33 | E33: 25.32 | F33: =D33*22 -> 139.26 | G33: =SUM(F33*C33) -> 557.04 | H33: 407.66 | I33: 298.1 | J33: =L33-K33 -> 71.814293 | K33: =(F33/$G$92)*Costs!$B$23 -> 205.96348 | L33: =N33/1.08 -> 277.77778 | M33: =L33*0.08 -> 22.222222 | N33: 300 | O33: =Table1[[#This Row],[Total Selling Price / Unit (MVR)]]*Table1[[#This Row],[Qty (NOS)]] -> 1200 | Q33: 17.86 | R33: =Q33*22 -> 392.92 | S33: 407.66 | T33: 18.53 | U33: 6.33 | V33: 139.26 | W33: 298.1 | X33: 300 | Y33: =T33*15.42 -> 285.7326 | Z33: =Y33*1.08 -> 308.59121 | AA33: =C33*Z33 -> 1234.3648 | AB33: =(T33+9)*15.42 -> 424.5126 | AC33: =AB33*1.08 -> 458.47361 | AD33: =C33*AC33 -> 1833.8944 | AE33: =T33*22 -> 407.66 | AF33: =AE33*1.08 -> 440.2728 | AG33: =C33*AF33 -> 1761.0912 | AH33: =(T33+9)*22 -> 605.66 | AI33: =AH33*1.08 -> 654.1128 | AJ33: =C33*AI33 -> 2616.4512 | AK33: =Table1[[#This Row],[Total Selling Price / Unit (MVR)]]/Table1[[#This Row],[CNF / Unit (MVR)]] -> 2.1542439 | AL33: =Table1[[#This Row],[Total Selling Price / Unit (MVR)]]-(Table1[[#This Row],[GST 8% (MVR)]]+Table1[[#This Row],[Weighted max expense (MVR)]]) -> 71.814293 | AM33: =Table1[[#This Row],[Profit / Unit (MVR)]]*Table1[[#This Row],[Qty (NOS)]] -> 287.25717
A34: Heeyul 24K Gold Eye Cream 40ml | B34: Eye Care | C34: 4 | D34: 1.96 | E34: 7.84 | F34: =D34*22 -> 43.12 | G34: =SUM(F34*C34) -> 172.48 | H34: 407.66 | I34: 300 | J34: =L34-K34 -> 241.78171 | K34: =(F34/$G$92)*Costs!$B$23 -> 63.773844 | L34: =N34/1.08 -> 305.55556 | M34: =L34*0.08 -> 24.444444 | N34: 330 | O34: =Table1[[#This Row],[Total Selling Price / Unit (MVR)]]*Table1[[#This Row],[Qty (NOS)]] -> 1320 | Q34: 17.86 | R34: =Q34*22 -> 392.92 | S34: 407.66 | T34: 18.53 | U34: 1.96 | V34: 43.12 | W34: 300 | X34: 330 | Y34: =T34*15.42 -> 285.7326 | Z34: =Y34*1.08 -> 308.59121 | AA34: =C34*Z34 -> 1234.3648 | AB34: =(T34+9)*15.42 -> 424.5126 | AC34: =AB34*1.08 -> 458.47361 | AD34: =C34*AC34 -> 1833.8944 | AE34: =T34*22 -> 407.66 | AF34: =AE34*1.08 -> 440.2728 | AG34: =C34*AF34 -> 1761.0912 | AH34: =(T34+9)*22 -> 605.66 | AI34: =AH34*1.08 -> 654.1128 | AJ34: =C34*AI34 -> 2616.4512 | AK34: =Table1[[#This Row],[Total Selling Price / Unit (MVR)]]/Table1[[#This Row],[CNF / Unit (MVR)]] -> 7.6530612 | AL34: =Table1[[#This Row],[Total Selling Price / Unit (MVR)]]-(Table1[[#This Row],[GST 8% (MVR)]]+Table1[[#This Row],[Weighted max expense (MVR)]]) -> 241.78171 | AM34: =Table1[[#This Row],[Profit / Unit (MVR)]]*Table1[[#This Row],[Qty (NOS)]] -> 967.12685
A35: Vitamin Hydrogel Eye Patch 90g / 60 sheets | B35: Eye Care | C35: 4 | D35: 6.33 | E35: 25.32 | F35: =D35*22 -> 139.26 | G35: =SUM(F35*C35) -> 557.04 | H35: N/A | I35: 298.1 | J35: =L35-K35 -> 71.814293 | K35: =(F35/$G$92)*Costs!$B$23 -> 205.96348 | L35: =N35/1.08 -> 277.77778 | M35: =L35*0.08 -> 22.222222 | N35: 300 | O35: =Table1[[#This Row],[Total Selling Price / Unit (MVR)]]*Table1[[#This Row],[Qty (NOS)]] -> 1200 | Q35: 17.86 | R35: =Q35*22 -> 392.92 | S35: N/A | T35: 18.53 | U35: 6.33 | V35: 139.26 | W35: 298.1 | X35: 300 | Y35: =T35*15.42 -> 285.7326 | Z35: =Y35*1.08 -> 308.59121 | AA35: =C35*Z35 -> 1234.3648 | AB35: =(T35+9)*15.42 -> 424.5126 | AC35: =AB35*1.08 -> 458.47361 | AD35: =C35*AC35 -> 1833.8944 | AE35: =T35*22 -> 407.66 | AF35: =AE35*1.08 -> 440.2728 | AG35: =C35*AF35 -> 1761.0912 | AH35: =(T35+9)*22 -> 605.66 | AI35: =AH35*1.08 -> 654.1128 | AJ35: =C35*AI35 -> 2616.4512 | AK35: =Table1[[#This Row],[Total Selling Price / Unit (MVR)]]/Table1[[#This Row],[CNF / Unit (MVR)]] -> 2.1542439 | AL35: =Table1[[#This Row],[Total Selling Price / Unit (MVR)]]-(Table1[[#This Row],[GST 8% (MVR)]]+Table1[[#This Row],[Weighted max expense (MVR)]]) -> 71.814293 | AM35: =Table1[[#This Row],[Profit / Unit (MVR)]]*Table1[[#This Row],[Qty (NOS)]] -> 287.25717
A36: The Glow Color Lip Balm #102 Smoothie Pink 3.6g | B36: Lips & Makeup | C36: 4 | D36: 3.34 | E36: 13.36 | F36: =D36*22 -> 73.48 | G36: =SUM(F36*C36) -> 293.92 | H36: N/A | I36: 125.84 | J36: =L36-K36 -> 67.250091 | K36: =(F36/$G$92)*Costs!$B$23 -> 108.67584 | L36: =N36/1.08 -> 175.92593 | M36: =L36*0.08 -> 14.074074 | N36: 190 | O36: =Table1[[#This Row],[Total Selling Price / Unit (MVR)]]*Table1[[#This Row],[Qty (NOS)]] -> 760 | Q36: 10.71 | R36: =Q36*22 -> 235.62 | S36: N/A | T36: 10 | U36: 3.34 | V36: 73.48 | W36: 125.84 | X36: 190 | Y36: =T36*15.42 -> 154.2 | Z36: =Y36*1.08 -> 166.536 | AA36: =C36*Z36 -> 666.144 | AB36: =(T36+9)*15.42 -> 292.98 | AC36: =AB36*1.08 -> 316.4184 | AD36: =C36*AC36 -> 1265.6736 | AE36: =T36*22 -> 220 | AF36: =AE36*1.08 -> 237.6 | AG36: =C36*AF36 -> 950.4 | AH36: =(T36+9)*22 -> 418 | AI36: =AH36*1.08 -> 451.44 | AJ36: =C36*AI36 -> 1805.76 | AK36: =Table1[[#This Row],[Total Selling Price / Unit (MVR)]]/Table1[[#This Row],[CNF / Unit (MVR)]] -> 2.5857376 | AL36: =Table1[[#This Row],[Total Selling Price / Unit (MVR)]]-(Table1[[#This Row],[GST 8% (MVR)]]+Table1[[#This Row],[Weighted max expense (MVR)]]) -> 67.250091 | AM36: =Table1[[#This Row],[Profit / Unit (MVR)]]*Table1[[#This Row],[Qty (NOS)]] -> 269.00036
A37: The Glow Color Lip Balm #103 Raspberry 3.6g | B37: Lips & Makeup | C37: 4 | D37: 3.34 | E37: 13.36 | F37: =D37*22 -> 73.48 | G37: =SUM(F37*C37) -> 293.92 | H37: N/A | I37: 125.84 | J37: =L37-K37 -> 67.250091 | K37: =(F37/$G$92)*Costs!$B$23 -> 108.67584 | L37: =N37/1.08 -> 175.92593 | M37: =L37*0.08 -> 14.074074 | N37: 190 | O37: =Table1[[#This Row],[Total Selling Price / Unit (MVR)]]*Table1[[#This Row],[Qty (NOS)]] -> 760 | Q37: 10.71 | R37: =Q37*22 -> 235.62 | S37: N/A | T37: 10 | U37: 3.34 | V37: 73.48 | W37: 125.84 | X37: 190 | Y37: =T37*15.42 -> 154.2 | Z37: =Y37*1.08 -> 166.536 | AA37: =C37*Z37 -> 666.144 | AB37: =(T37+9)*15.42 -> 292.98 | AC37: =AB37*1.08 -> 316.4184 | AD37: =C37*AC37 -> 1265.6736 | AE37: =T37*22 -> 220 | AF37: =AE37*1.08 -> 237.6 | AG37: =C37*AF37 -> 950.4 | AH37: =(T37+9)*22 -> 418 | AI37: =AH37*1.08 -> 451.44 | AJ37: =C37*AI37 -> 1805.76 | AK37: =Table1[[#This Row],[Total Selling Price / Unit (MVR)]]/Table1[[#This Row],[CNF / Unit (MVR)]] -> 2.5857376 | AL37: =Table1[[#This Row],[Total Selling Price / Unit (MVR)]]-(Table1[[#This Row],[GST 8% (MVR)]]+Table1[[#This Row],[Weighted max expense (MVR)]]) -> 67.250091 | AM37: =Table1[[#This Row],[Profit / Unit (MVR)]]*Table1[[#This Row],[Qty (NOS)]] -> 269.00036
A38: The Glow Color Lip Balm #104 Rosewood 3.6g | B38: Lips & Makeup | C38: 4 | D38: 3.34 | E38: 13.36 | F38: =D38*22 -> 73.48 | G38: =SUM(F38*C38) -> 293.92 | H38: N/A | I38: 125.84 | J38: =L38-K38 -> 67.250091 | K38: =(F38/$G$92)*Costs!$B$23 -> 108.67584 | L38: =N38/1.08 -> 175.92593 | M38: =L38*0.08 -> 14.074074 | N38: 190 | O38: =Table1[[#This Row],[Total Selling Price / Unit (MVR)]]*Table1[[#This Row],[Qty (NOS)]] -> 760 | Q38: 10.71 | R38: =Q38*22 -> 235.62 | S38: N/A | T38: 10 | U38: 3.34 | V38: 73.48 | W38: 125.84 | X38: 190 | Y38: =T38*15.42 -> 154.2 | Z38: =Y38*1.08 -> 166.536 | AA38: =C38*Z38 -> 666.144 | AB38: =(T38+9)*15.42 -> 292.98 | AC38: =AB38*1.08 -> 316.4184 | AD38: =C38*AC38 -> 1265.6736 | AE38: =T38*22 -> 220 | AF38: =AE38*1.08 -> 237.6 | AG38: =C38*AF38 -> 950.4 | AH38: =(T38+9)*22 -> 418 | AI38: =AH38*1.08 -> 451.44 | AJ38: =C38*AI38 -> 1805.76 | AK38: =Table1[[#This Row],[Total Selling Price / Unit (MVR)]]/Table1[[#This Row],[CNF / Unit (MVR)]] -> 2.5857376 | AL38: =Table1[[#This Row],[Total Selling Price / Unit (MVR)]]-(Table1[[#This Row],[GST 8% (MVR)]]+Table1[[#This Row],[Weighted max expense (MVR)]]) -> 67.250091 | AM38: =Table1[[#This Row],[Profit / Unit (MVR)]]*Table1[[#This Row],[Qty (NOS)]] -> 269.00036
A39: Aloe Solution Mask Pack 25g x 10pcs | B39: Mask Packs | C39: 4 | D39: 2.13 | E39: 8.52 | F39: =D39*22 -> 46.86 | G39: =SUM(F39*C39) -> 187.44 | H39: 440 | I39: 47.74 | J39: =L39-K39 -> 143.65771 | K39: =(F39/$G$92)*Costs!$B$23 -> 69.305248 | L39: =N39/1.08 -> 212.96296 | M39: =L39*0.08 -> 17.037037 | N39: 230 | O39: =Table1[[#This Row],[Total Selling Price / Unit (MVR)]]*Table1[[#This Row],[Qty (NOS)]] -> 920 | Q39: 7.14 | R39: =Q39*22 -> 157.08 | S39: 440 | T39: 20 | U39: 2.13 | V39: 46.86 | W39: 47.74 | X39: 230 | Y39: =T39*15.42 -> 308.4 | Z39: =Y39*1.08 -> 333.072 | AA39: =C39*Z39 -> 1332.288 | AB39: =(T39+9)*15.42 -> 447.18 | AC39: =AB39*1.08 -> 482.9544 | AD39: =C39*AC39 -> 1931.8176 | AE39: =T39*22 -> 440 | AF39: =AE39*1.08 -> 475.2 | AG39: =C39*AF39 -> 1900.8 | AH39: =(T39+9)*22 -> 638 | AI39: =AH39*1.08 -> 689.04 | AJ39: =C39*AI39 -> 2756.16 | AK39: =Table1[[#This Row],[Total Selling Price / Unit (MVR)]]/Table1[[#This Row],[CNF / Unit (MVR)]] -> 4.9082373 | AL39: =Table1[[#This Row],[Total Selling Price / Unit (MVR)]]-(Table1[[#This Row],[GST 8% (MVR)]]+Table1[[#This Row],[Weighted max expense (MVR)]]) -> 143.65771 | AM39: =Table1[[#This Row],[Profit / Unit (MVR)]]*Table1[[#This Row],[Qty (NOS)]] -> 574.63086
A40: Cica Solution Mask Pack 25g x 10pcs | B40: Mask Packs | C40: 4 | D40: 2.13 | E40: 8.52 | F40: =D40*22 -> 46.86 | G40: =SUM(F40*C40) -> 187.44 | H40: 440 | I40: 47.74 | J40: =L40-K40 -> 143.65771 | K40: =(F40/$G$92)*Costs!$B$23 -> 69.305248 | L40: =N40/1.08 -> 212.96296 | M40: =L40*0.08 -> 17.037037 | N40: 230 | O40: =Table1[[#This Row],[Total Selling Price / Unit (MVR)]]*Table1[[#This Row],[Qty (NOS)]] -> 920 | Q40: 7.14 | R40: =Q40*22 -> 157.08 | S40: 440 | T40: 20 | U40: 2.13 | V40: 46.86 | W40: 47.74 | X40: 230 | Y40: =T40*15.42 -> 308.4 | Z40: =Y40*1.08 -> 333.072 | AA40: =C40*Z40 -> 1332.288 | AB40: =(T40+9)*15.42 -> 447.18 | AC40: =AB40*1.08 -> 482.9544 | AD40: =C40*AC40 -> 1931.8176 | AE40: =T40*22 -> 440 | AF40: =AE40*1.08 -> 475.2 | AG40: =C40*AF40 -> 1900.8 | AH40: =(T40+9)*22 -> 638 | AI40: =AH40*1.08 -> 689.04 | AJ40: =C40*AI40 -> 2756.16 | AK40: =Table1[[#This Row],[Total Selling Price / Unit (MVR)]]/Table1[[#This Row],[CNF / Unit (MVR)]] -> 4.9082373 | AL40: =Table1[[#This Row],[Total Selling Price / Unit (MVR)]]-(Table1[[#This Row],[GST 8% (MVR)]]+Table1[[#This Row],[Weighted max expense (MVR)]]) -> 143.65771 | AM40: =Table1[[#This Row],[Profit / Unit (MVR)]]*Table1[[#This Row],[Qty (NOS)]] -> 574.63086
A41: Hyaluronic Collagen Solution Mask Pack 25g x 10pcs | B41: Mask Packs | C41: 4 | D41: 2.13 | E41: 8.52 | F41: =D41*22 -> 46.86 | G41: =SUM(F41*C41) -> 187.44 | H41: 440 | I41: 47.74 | J41: =L41-K41 -> 143.65771 | K41: =(F41/$G$92)*Costs!$B$23 -> 69.305248 | L41: =N41/1.08 -> 212.96296 | M41: =L41*0.08 -> 17.037037 | N41: 230 | O41: =Table1[[#This Row],[Total Selling Price / Unit (MVR)]]*Table1[[#This Row],[Qty (NOS)]] -> 920 | Q41: 7.14 | R41: =Q41*22 -> 157.08 | S41: 440 | T41: 20 | U41: 2.13 | V41: 46.86 | W41: 47.74 | X41: 230 | Y41: =T41*15.42 -> 308.4 | Z41: =Y41*1.08 -> 333.072 | AA41: =C41*Z41 -> 1332.288 | AB41: =(T41+9)*15.42 -> 447.18 | AC41: =AB41*1.08 -> 482.9544 | AD41: =C41*AC41 -> 1931.8176 | AE41: =T41*22 -> 440 | AF41: =AE41*1.08 -> 475.2 | AG41: =C41*AF41 -> 1900.8 | AH41: =(T41+9)*22 -> 638 | AI41: =AH41*1.08 -> 689.04 | AJ41: =C41*AI41 -> 2756.16 | AK41: =Table1[[#This Row],[Total Selling Price / Unit (MVR)]]/Table1[[#This Row],[CNF / Unit (MVR)]] -> 4.9082373 | AL41: =Table1[[#This Row],[Total Selling Price / Unit (MVR)]]-(Table1[[#This Row],[GST 8% (MVR)]]+Table1[[#This Row],[Weighted max expense (MVR)]]) -> 143.65771 | AM41: =Table1[[#This Row],[Profit / Unit (MVR)]]*Table1[[#This Row],[Qty (NOS)]] -> 574.63086
...

Sheet Final Pricing Sheet
A1: Product Name (as invoiced) | B1: Category | C1: Qty (NOS) | D1: CNF / Unit (invoiced USD) | E1: CNF / Total Units (invoiced USD) | F1: CNF / Unit (MVR) | G1: CNF / Total Units (MVR) | H1: Lebelage Price w/o Shipping (MVR) | I1: Yesstyle Prices w/o Shipping (MVR) | J1: Base Profit / Unit (MVR) | K1: Weighted max expense (MVR) | L1: Selling price w/o GST (MVR) | M1: GST 8% (MVR) | N1: Total Selling Price / Unit (MVR) | O1: Total Selling Price / Total Units (MVR) | P1: Proposed New Listing Price Total Units (MVR) | Q1: Proposed New Listing Price / Unit (MVR)2 | R1: Proposed New Discounting Price / Unit (MVR) | S1: Lebelage Retail Price as per Kim's Catalogue (USD) | T1: Lebelage Retail Price as per Kim's Catalogue (MVR) | U1: Lebelage Price w/o Shipping (MVR)2 | V1: Lebelage Retail Price (USD) | W1: CNF / Unit (invoiced USD)2 | X1: CNF*2*Qty (MVR) | Y1: CNF*2 Rounded Off (MVR) | Z1: CNF*2 (MVR) | AA1: CNF / Unit (MVR)2 | AB1: Yesstyle Prices w/o Shipping (MVR)2 | AC1: Total Selling Price / Unit (MVR)2 | AD1: Minimum Selling Price w/o GST (MVR) | AE1: Minimum Selling Price w/ GST (MVR) | AF1: Minimum Selling Price w/ GST for Total Units (MVR) | AG1: Alt 1 Median Selling Price w/o GST (MVR) | AH1: Alt 1 Median Selling Price w/ GST (MVR) | AI1: Alt 1 Median Selling Price w/ GST for Total Units (MVR) | AJ1: Alt 2 Median Selling Price w/o GST (MVR)2 | AK1: Alt 2 Median Selling Price w/ GST (MVR)2 | AL1: Alt 2 Median Selling Price w/ GST for Total Units (MVR) | AM1: Maximum Selling Price w/o GST (MVR) | AN1: Maximum Selling Price w/ GST (MVR) | AO1: Maximum Selling Price w/ GST for Total Units (MVR)2 | AP1: Revenue to CNF ratio (%) | AQ1: Profit / Unit (MVR) | AR1: Total Profit (MVR)
N2: Current Price | O2: Current Expected Revenue on 100% sales | P2: Listing Price Total Products | Q2: Listing Price | R2: Discount Price | T2: Kim's Lebelage Catalogue | U2: Lebelage Website Price w/o Shipping | X2: Miniestmum Total Selling Price | Y2: Miniestmum Selling Price Rounded Off | Z2: Miniestmum Selling Price | AA2: CNF | AB2: Yesstyle Price w/o Shipping | AD2: (Lebelage selling price)*15.42 | AE2: Per Product | AF2: "Minimum Selling Price" Revenue on 100% sales | AG2: (Lebelage selling price + 9 usd shipping)*15.42 | AH2: Per Product | AI2: "Alt 1 Median Selling Price" Revenue on 100% sales | AJ2: (Lebelage selling price)*22 | AK2: Per Product | AL2: "Alt 2 Median Selling Price" Revenue on 100% sales | AM2: (Lebelage selling price + 9usd shipping)*22 | AN2: Per Product | AO2: "Maximum Selling Price" Revenue on 100% sales
A3: Aloe Bubble Chewy Foam 200ml | B3: Cleansing & Peeling | C3: 4 | D3: 7.06 | E3: 28.24 | F3: =D3*22 -> 155.32 | G3: =SUM(F3*C3) -> 621.28 | H3: 487.52 | I3: 322.74 | J3: =L3-K3 -> 140.65438 | K3: =(F3/$G$92)*Costs!$B$23 -> 229.71599 | L3: =N3/1.08 -> 370.37037 | M3: =L3*0.08 -> 29.62963 | N3: 400 | O3: =Table13[[#This Row],[Total Selling Price / Unit (MVR)]]*Table13[[#This Row],[Qty (NOS)]] -> 1600 | P3: =Q3*C3 -> 1600 | Q3: 400 | R3: =Q3*0.8 -> 320 | S3: 21.36 | T3: =S3*22 -> 469.92 | U3: 487.52 | V3: 22.16 | W3: 7.06 | X3: =Z3*C3 -> 1242.56 | Y3: 315 | Z3: =AA3*2 -> 310.64 | AA3: 155.32 | AB3: 322.74 | AC3: 400 | AD3: =V3*15.42 -> 341.7072 | AE3: =AD3*1.08 -> 369.04378 | AF3: =C3*AE3 -> 1476.1751 | AG3: =(V3+9)*15.42 -> 480.4872 | AH3: =AG3*1.08 -> 518.92618 | AI3: =C3*AH3 -> 2075.7047 | AJ3: =V3*22 -> 487.52 | AK3: =AJ3*1.08 -> 526.5216 | AL3: =C3*AK3 -> 2106.0864 | AM3: =(V3+9)*22 -> 685.52 | AN3: =AM3*1.08 -> 740.3616 | AO3: =C3*AN3 -> 2961.4464 | AP3: =Table13[[#This Row],[Total Selling Price / Unit (MVR)]]/Table13[[#This Row],[CNF / Unit (MVR)]] -> 2.5753284 | AQ3: =Table13[[#This Row],[Total Selling Price / Unit (MVR)]]-(Table13[[#This Row],[GST 8% (MVR)]]+Table13[[#This Row],[Weighted max expense (MVR)]]) -> 140.65438 | AR3: =Table13[[#This Row],[Profit / Unit (MVR)]]*Table13[[#This Row],[Qty (NOS)]] -> 562.61753
A4: AVOCADO REVITAL CLEANSING FOAM 180ml | B4: Cleansing & Peeling | C4: 4 | D4: 3.9 | E4: 15.6 | F4: =D4*22 -> 85.8 | G4: =SUM(F4*C4) -> 343.2 | H4: 119.02 | I4: 176.22 | J4: =L4-K4 -> 39.769733 | K4: =(F4/$G$92)*Costs!$B$23 -> 126.89693 | L4: =N4/1.08 -> 166.66667 | M4: =L4*0.08 -> 13.333333 | N4: 180 | O4: =Table13[[#This Row],[Total Selling Price / Unit (MVR)]]*Table13[[#This Row],[Qty (NOS)]] -> 720 | P4: =Q4*C4 -> 720 | Q4: 180 | R4: =Q4*0.8 -> 144 | S4: 5.21 | T4: =S4*22 -> 114.62 | U4: 119.02 | V4: 5.41 | W4: 3.9 | X4: =Z4*C4 -> 686.4 | Y4: 175 | Z4: =AA4*2 -> 171.6 | AA4: 85.8 | AB4: 176.22 | AC4: 180 | AD4: =V4*15.42 -> 83.4222 | AE4: =AD4*1.08 -> 90.095976 | AF4: =C4*AE4 -> 360.3839 | AG4: =(V4+9)*15.42 -> 222.2022 | AH4: =AG4*1.08 -> 239.97838 | AI4: =C4*AH4 -> 959.9135 | AJ4: =V4*22 -> 119.02 | AK4: =AJ4*1.08 -> 128.5416 | AL4: =C4*AK4 -> 514.1664 | AM4: =(V4+9)*22 -> 317.02 | AN4: =AM4*1.08 -> 342.3816 | AO4: =C4*AN4 -> 1369.5264 | AP4: =Table13[[#This Row],[Total Selling Price / Unit (MVR)]]/Table13[[#This Row],[CNF / Unit (MVR)]] -> 2.0979021 | AQ4: =Table13[[#This Row],[Total Selling Price / Unit (MVR)]]-(Table13[[#This Row],[GST 8% (MVR)]]+Table13[[#This Row],[Weighted max expense (MVR)]]) -> 39.769733 | AR4: =Table13[[#This Row],[Profit / Unit (MVR)]]*Table13[[#This Row],[Qty (NOS)]] -> 159.07893 | AT4: Total Revenue | AU4: =O92 -> 136161
A5: Centella Bubble Chewy Foam 200ml | B5: Cleansing & Peeling | C5: 7 | D5: 7.06 | E5: 49.42 | F5: =D5*22 -> 155.32 | G5: =SUM(F5*C5) -> 1087.24 | H5: 487.52 | I5: 322.74 | J5: =L5-K5 -> 140.65438 | K5: =(F5/$G$92)*Costs!$B$23 -> 229.71599 | L5: =N5/1.08 -> 370.37037 | M5: =L5*0.08 -> 29.62963 | N5: 400 | O5: =Table13[[#This Row],[Total Selling Price / Unit (MVR)]]*Table13[[#This Row],[Qty (NOS)]] -> 2800 | P5: =Q5*C5 -> 2800 | Q5: 400 | R5: =Q5*0.8 -> 320 | S5: 21.36 | T5: =S5*22 -> 469.92 | U5: 487.52 | V5: 22.16 | W5: 7.06 | X5: =Z5*C5 -> 2174.48 | Y5: 315 | Z5: =AA5*2 -> 310.64 | AA5: 155.32 | AB5: 322.74 | AC5: 400 | AD5: =V5*15.42 -> 341.7072 | AE5: =AD5*1.08 -> 369.04378 | AF5: =C5*AE5 -> 2583.3064 | AG5: =(V5+9)*15.42 -> 480.4872 | AH5: =AG5*1.08 -> 518.92618 | AI5: =C5*AH5 -> 3632.4832 | AJ5: =V5*22 -> 487.52 | AK5: =AJ5*1.08 -> 526.5216 | AL5: =C5*AK5 -> 3685.6512 | AM5: =(V5+9)*22 -> 685.52 | AN5: =AM5*1.08 -> 740.3616 | AO5: =C5*AN5 -> 5182.5312 | AP5: =Table13[[#This Row],[Total Selling Price / Unit (MVR)]]/Table13[[#This Row],[CNF / Unit (MVR)]] -> 2.5753284 | AQ5: =Table13[[#This Row],[Total Selling Price / Unit (MVR)]]-(Table13[[#This Row],[GST 8% (MVR)]]+Table13[[#This Row],[Weighted max expense (MVR)]]) -> 140.65438 | AR5: =Table13[[#This Row],[Profit / Unit (MVR)]]*Table13[[#This Row],[Qty (NOS)]] -> 984.58068 | AT5: Total Cost | AU5: =Costs!B23 -> 69267.83
A6: Charcoal Clay 2in1 Pack Foam 120ml | B6: Cleansing & Peeling | C6: 7 | D6: 4.24 | E6: 29.68 | F6: =D6*22 -> 93.28 | G6: =SUM(F6*C6) -> 652.96 | H6: 407.66 | I6: 162.36 | J6: =L6-K6 -> 186.11433 | K6: =(F6/$G$92)*Costs!$B$23 -> 137.95974 | L6: =N6/1.08 -> 324.07407 | M6: =L6*0.08 -> 25.925926 | N6: 350 | O6: =Table13[[#This Row],[Total Selling Price / Unit (MVR)]]*Table13[[#This Row],[Qty (NOS)]] -> 2450 | P6: =Q6*C6 -> 2240 | Q6: 320 | R6: =Q6*0.8 -> 256 | S6: 17.86 | T6: =S6*22 -> 392.92 | U6: 407.66 | V6: 18.53 | W6: 4.24 | X6: =Z6*C6 -> 1305.92 | Y6: 190 | Z6: =AA6*2 -> 186.56 | AA6: 93.28 | AB6: 162.36 | AC6: 350 | AD6: =V6*15.42 -> 285.7326 | AE6: =AD6*1.08 -> 308.59121 | AF6: =C6*AE6 -> 2160.1385 | AG6: =(V6+9)*15.42 -> 424.5126 | AH6: =AG6*1.08 -> 458.47361 | AI6: =C6*AH6 -> 3209.3153 | AJ6: =V6*22 -> 407.66 | AK6: =AJ6*1.08 -> 440.2728 | AL6: =C6*AK6 -> 3081.9096 | AM6: =(V6+9)*22 -> 605.66 | AN6: =AM6*1.08 -> 654.1128 | AO6: =C6*AN6 -> 4578.7896 | AP6: =Table13[[#This Row],[Total Selling Price / Unit (MVR)]]/Table13[[#This Row],[CNF / Unit (MVR)]] -> 3.7521441 | AQ6: =Table13[[#This Row],[Total Selling Price / Unit (MVR)]]-(Table13[[#This Row],[GST 8% (MVR)]]+Table13[[#This Row],[Weighted max expense (MVR)]]) -> 186.11433 | AR6: =Table13[[#This Row],[Profit / Unit (MVR)]]*Table13[[#This Row],[Qty (NOS)]] -> 1302.8003 | AT6: Total Profit | AU6: =AU4-AU5 -> 66893.17
